Traceback (most recent call last):
  File "C:\Users\unerue\miniconda3\envs\vision\lib\site-packages\jupyter_cache\executors\utils.py", line 51, in single_nb_execution
    executenb(
  File "C:\Users\unerue\miniconda3\envs\vision\lib\site-packages\nbclient\client.py", line 1204, in execute
    return NotebookClient(nb=nb, resources=resources, km=km, **kwargs).execute()
  File "C:\Users\unerue\miniconda3\envs\vision\lib\site-packages\nbclient\util.py", line 84, in wrapped
    return just_run(coro(*args, **kwargs))
  File "C:\Users\unerue\miniconda3\envs\vision\lib\site-packages\nbclient\util.py", line 62, in just_run
    return loop.run_until_complete(coro)
  File "C:\Users\unerue\miniconda3\envs\vision\lib\asyncio\base_events.py", line 642, in run_until_complete
    return future.result()
  File "C:\Users\unerue\miniconda3\envs\vision\lib\site-packages\nbclient\client.py", line 663, in async_execute
    await self.async_execute_cell(
  File "C:\Users\unerue\miniconda3\envs\vision\lib\site-packages\nbclient\client.py", line 965, in async_execute_cell
    await self._check_raise_for_error(cell, cell_index, exec_reply)
  File "C:\Users\unerue\miniconda3\envs\vision\lib\site-packages\nbclient\client.py", line 862, in _check_raise_for_error
    raise CellExecutionError.from_cell_and_msg(cell, exec_reply_content)
nbclient.exceptions.CellExecutionError: An error occurred while executing the following cell:
------------------
import numpy as np
import matplotlib.pyplot as plt
from skimage import io, color
%matplotlib inline

image = io.imread('./img/cat-01.jpg')
print(type(image))

image1 = color.rgb2lab(image)
image1[...,1] = image1[...,2] = 0
image1 = color.lab2rgb(image1)

fig, axes = plt.subplots(ncols=2)
axes[0].imshow(im)
axes[0].axis('off')
axes[0].set_title('Original image')
axes[1].imshow(im1)
axes[1].axis('off')
axes[1].set_title('Gray scale image')
fig.tight_layout()
plt.show()
------------------

[1;31m---------------------------------------------------------------------------[0m
[1;31mNameError[0m                                 Traceback (most recent call last)
Input [1;32mIn [4][0m, in [0;36m<cell line: 14>[1;34m()[0m
[0;32m     11[0m image1 [38;5;241m=[39m color[38;5;241m.[39mlab2rgb(image1)
[0;32m     13[0m fig, axes [38;5;241m=[39m plt[38;5;241m.[39msubplots(ncols[38;5;241m=[39m[38;5;241m2[39m)
[1;32m---> 14[0m axes[[38;5;241m0[39m][38;5;241m.[39mimshow([43mim[49m)
[0;32m     15[0m axes[[38;5;241m0[39m][38;5;241m.[39maxis([38;5;124m'[39m[38;5;124moff[39m[38;5;124m'[39m)
[0;32m     16[0m axes[[38;5;241m0[39m][38;5;241m.[39mset_title([38;5;124m'[39m[38;5;124mOriginal image[39m[38;5;124m'[39m)

[1;31mNameError[0m: name 'im' is not defined
NameError: name 'im' is not defined

