Traceback (most recent call last):
  File "C:\Users\unerue\miniconda3\envs\vision\lib\site-packages\jupyter_cache\executors\utils.py", line 51, in single_nb_execution
    executenb(
  File "C:\Users\unerue\miniconda3\envs\vision\lib\site-packages\nbclient\client.py", line 1204, in execute
    return NotebookClient(nb=nb, resources=resources, km=km, **kwargs).execute()
  File "C:\Users\unerue\miniconda3\envs\vision\lib\site-packages\nbclient\util.py", line 84, in wrapped
    return just_run(coro(*args, **kwargs))
  File "C:\Users\unerue\miniconda3\envs\vision\lib\site-packages\nbclient\util.py", line 62, in just_run
    return loop.run_until_complete(coro)
  File "C:\Users\unerue\miniconda3\envs\vision\lib\asyncio\base_events.py", line 642, in run_until_complete
    return future.result()
  File "C:\Users\unerue\miniconda3\envs\vision\lib\site-packages\nbclient\client.py", line 663, in async_execute
    await self.async_execute_cell(
  File "C:\Users\unerue\miniconda3\envs\vision\lib\site-packages\nbclient\client.py", line 965, in async_execute_cell
    await self._check_raise_for_error(cell, cell_index, exec_reply)
  File "C:\Users\unerue\miniconda3\envs\vision\lib\site-packages\nbclient\client.py", line 862, in _check_raise_for_error
    raise CellExecutionError.from_cell_and_msg(cell, exec_reply_content)
nbclient.exceptions.CellExecutionError: An error occurred while executing the following cell:
------------------
[i[1]['Fitness'] for i in result]
------------------

[1;31m---------------------------------------------------------------------------[0m
[1;31mNameError[0m                                 Traceback (most recent call last)
Input [1;32mIn [6][0m, in [0;36m<cell line: 1>[1;34m()[0m
[1;32m----> 1[0m [i[[38;5;241m1[39m][[38;5;124m'[39m[38;5;124mFitness[39m[38;5;124m'[39m] [38;5;28;01mfor[39;00m i [38;5;129;01min[39;00m [43mresult[49m]

[1;31mNameError[0m: name 'result' is not defined
NameError: name 'result' is not defined

