Traceback (most recent call last):
  File "C:\Users\unerue\miniconda3\envs\vision\lib\site-packages\jupyter_cache\executors\utils.py", line 51, in single_nb_execution
    executenb(
  File "C:\Users\unerue\miniconda3\envs\vision\lib\site-packages\nbclient\client.py", line 1204, in execute
    return NotebookClient(nb=nb, resources=resources, km=km, **kwargs).execute()
  File "C:\Users\unerue\miniconda3\envs\vision\lib\site-packages\nbclient\util.py", line 84, in wrapped
    return just_run(coro(*args, **kwargs))
  File "C:\Users\unerue\miniconda3\envs\vision\lib\site-packages\nbclient\util.py", line 62, in just_run
    return loop.run_until_complete(coro)
  File "C:\Users\unerue\miniconda3\envs\vision\lib\asyncio\base_events.py", line 642, in run_until_complete
    return future.result()
  File "C:\Users\unerue\miniconda3\envs\vision\lib\site-packages\nbclient\client.py", line 663, in async_execute
    await self.async_execute_cell(
  File "C:\Users\unerue\miniconda3\envs\vision\lib\site-packages\nbclient\client.py", line 965, in async_execute_cell
    await self._check_raise_for_error(cell, cell_index, exec_reply)
  File "C:\Users\unerue\miniconda3\envs\vision\lib\site-packages\nbclient\client.py", line 862, in _check_raise_for_error
    raise CellExecutionError.from_cell_and_msg(cell, exec_reply_content)
nbclient.exceptions.CellExecutionError: An error occurred while executing the following cell:
------------------
import numpy as np
from sklearn.metrics.pairwise import euclidean_distances


class TravelingSalesman:
    """Generate a Traveling Salesman Problem
    """
    def __init__(self, x, y, num_cities, random_state=None):
        self.x = x
        self.y = y
        self.num_cities = num_cities
        self.random_state = random_state

    def generate(self):
        np.random.seed(self.random_state)
        x = np.random.randint(self.x, size=self.num_cities)
        y = np.random.randint(self.y, size=self.num_cities)
        self.coords = np.column_stack((x, y))
              
        return np.int32(euclidean_distances(coords))
------------------

[1;31m---------------------------------------------------------------------------[0m
[1;31mModuleNotFoundError[0m                       Traceback (most recent call last)
Input [1;32mIn [1][0m, in [0;36m<cell line: 2>[1;34m()[0m
[0;32m      1[0m [38;5;28;01mimport[39;00m [38;5;21;01mnumpy[39;00m [38;5;28;01mas[39;00m [38;5;21;01mnp[39;00m
[1;32m----> 2[0m [38;5;28;01mfrom[39;00m [38;5;21;01msklearn[39;00m[38;5;21;01m.[39;00m[38;5;21;01mmetrics[39;00m[38;5;21;01m.[39;00m[38;5;21;01mpairwise[39;00m [38;5;28;01mimport[39;00m euclidean_distances
[0;32m      5[0m [38;5;28;01mclass[39;00m [38;5;21;01mTravelingSalesman[39;00m:
[0;32m      6[0m     [38;5;124;03m"""Generate a Traveling Salesman Problem[39;00m
[0;32m      7[0m [38;5;124;03m    """[39;00m

[1;31mModuleNotFoundError[0m: No module named 'sklearn'
ModuleNotFoundError: No module named 'sklearn'

