Traceback (most recent call last):
  File "C:\Users\unerue\miniconda3\envs\vision\lib\site-packages\jupyter_cache\executors\utils.py", line 51, in single_nb_execution
    executenb(
  File "C:\Users\unerue\miniconda3\envs\vision\lib\site-packages\nbclient\client.py", line 1204, in execute
    return NotebookClient(nb=nb, resources=resources, km=km, **kwargs).execute()
  File "C:\Users\unerue\miniconda3\envs\vision\lib\site-packages\nbclient\util.py", line 84, in wrapped
    return just_run(coro(*args, **kwargs))
  File "C:\Users\unerue\miniconda3\envs\vision\lib\site-packages\nbclient\util.py", line 62, in just_run
    return loop.run_until_complete(coro)
  File "C:\Users\unerue\miniconda3\envs\vision\lib\asyncio\base_events.py", line 642, in run_until_complete
    return future.result()
  File "C:\Users\unerue\miniconda3\envs\vision\lib\site-packages\nbclient\client.py", line 663, in async_execute
    await self.async_execute_cell(
  File "C:\Users\unerue\miniconda3\envs\vision\lib\site-packages\nbclient\client.py", line 965, in async_execute_cell
    await self._check_raise_for_error(cell, cell_index, exec_reply)
  File "C:\Users\unerue\miniconda3\envs\vision\lib\site-packages\nbclient\client.py", line 862, in _check_raise_for_error
    raise CellExecutionError.from_cell_and_msg(cell, exec_reply_content)
nbclient.exceptions.CellExecutionError: An error occurred while executing the following cell:
------------------
from pulp import *
from ortools.utils import output

# Define problem
prob = LpProblem(name='Workforce Scheduling', sense=LpMinimize)

# Create decision variables and non-negative constraint
x1 = LpVariable(name='X1', lowBound=0, cat='Continuous')
x2 = LpVariable(name='X2', lowBound=0, cat='Continuous')
x3 = LpVariable(name='X3', lowBound=0, cat='Continuous')
x4 = LpVariable(name='X4', lowBound=0, cat='Continuous')
x5 = LpVariable(name='X5', lowBound=0, cat='Continuous')

# Set objective function
prob += 7*x1 + 6*x2 + 7.5*x3 + 8*x4 + 9.5*x5

# Set constraints
prob += x1 >= 48
prob += x1 + x2 >= 79
prob += x1 + x2 >= 65
prob += x1 + x2 + x3 >= 87
prob += x2 + x3 >= 64
prob += x3 + x4 >= 73
prob += x3 + x4 >= 82
prob += x4 >= 43
prob += x4 + x5 >= 52
prob += x5 >= 15

# Solving problem
prob.solve()
output(prob, sensitivity=False)
------------------

[1;31m---------------------------------------------------------------------------[0m
[1;31mModuleNotFoundError[0m                       Traceback (most recent call last)
Input [1;32mIn [2][0m, in [0;36m<cell line: 1>[1;34m()[0m
[1;32m----> 1[0m [38;5;28;01mfrom[39;00m [38;5;21;01mpulp[39;00m [38;5;28;01mimport[39;00m [38;5;241m*[39m
[0;32m      2[0m [38;5;28;01mfrom[39;00m [38;5;21;01mortools[39;00m[38;5;21;01m.[39;00m[38;5;21;01mutils[39;00m [38;5;28;01mimport[39;00m output
[0;32m      4[0m [38;5;66;03m# Define problem[39;00m

[1;31mModuleNotFoundError[0m: No module named 'pulp'
ModuleNotFoundError: No module named 'pulp'

