Traceback (most recent call last):
  File "C:\Users\unerue\miniconda3\envs\jupyterbook\lib\site-packages\jupyter_cache\executors\utils.py", line 58, in single_nb_execution
    executenb(
  File "C:\Users\unerue\miniconda3\envs\jupyterbook\lib\site-packages\nbclient\client.py", line 1204, in execute
    return NotebookClient(nb=nb, resources=resources, km=km, **kwargs).execute()
  File "C:\Users\unerue\miniconda3\envs\jupyterbook\lib\site-packages\nbclient\util.py", line 84, in wrapped
    return just_run(coro(*args, **kwargs))
  File "C:\Users\unerue\miniconda3\envs\jupyterbook\lib\site-packages\nbclient\util.py", line 62, in just_run
    return loop.run_until_complete(coro)
  File "C:\Users\unerue\miniconda3\envs\jupyterbook\lib\asyncio\base_events.py", line 647, in run_until_complete
    return future.result()
  File "C:\Users\unerue\miniconda3\envs\jupyterbook\lib\site-packages\nbclient\client.py", line 663, in async_execute
    await self.async_execute_cell(
  File "C:\Users\unerue\miniconda3\envs\jupyterbook\lib\site-packages\nbclient\client.py", line 965, in async_execute_cell
    await self._check_raise_for_error(cell, cell_index, exec_reply)
  File "C:\Users\unerue\miniconda3\envs\jupyterbook\lib\site-packages\nbclient\client.py", line 862, in _check_raise_for_error
    raise CellExecutionError.from_cell_and_msg(cell, exec_reply_content)
nbclient.exceptions.CellExecutionError: An error occurred while executing the following cell:
------------------
a = Vector(-1, 1)
b = Vector(2, 2)
print(a + b)
print(a * 2)
a.x = 7
------------------

[1;31m---------------------------------------------------------------------------[0m
[1;31mAttributeError[0m                            Traceback (most recent call last)
Cell [1;32mIn[13], line 5[0m
[0;32m      3[0m [38;5;28mprint[39m(a [38;5;241m+[39m b)
[0;32m      4[0m [38;5;28mprint[39m(a [38;5;241m*[39m [38;5;241m2[39m)
[1;32m----> 5[0m a[38;5;241m.[39mx [38;5;241m=[39m [38;5;241m7[39m

[1;31mAttributeError[0m: can't set attribute
AttributeError: can't set attribute

