Traceback (most recent call last):
  File "C:\Users\unerue\miniconda3\envs\jupyterbook\lib\site-packages\jupyter_cache\executors\utils.py", line 58, in single_nb_execution
    executenb(
  File "C:\Users\unerue\miniconda3\envs\jupyterbook\lib\site-packages\nbclient\client.py", line 1204, in execute
    return NotebookClient(nb=nb, resources=resources, km=km, **kwargs).execute()
  File "C:\Users\unerue\miniconda3\envs\jupyterbook\lib\site-packages\nbclient\util.py", line 84, in wrapped
    return just_run(coro(*args, **kwargs))
  File "C:\Users\unerue\miniconda3\envs\jupyterbook\lib\site-packages\nbclient\util.py", line 62, in just_run
    return loop.run_until_complete(coro)
  File "C:\Users\unerue\miniconda3\envs\jupyterbook\lib\asyncio\base_events.py", line 647, in run_until_complete
    return future.result()
  File "C:\Users\unerue\miniconda3\envs\jupyterbook\lib\site-packages\nbclient\client.py", line 663, in async_execute
    await self.async_execute_cell(
  File "C:\Users\unerue\miniconda3\envs\jupyterbook\lib\site-packages\nbclient\client.py", line 965, in async_execute_cell
    await self._check_raise_for_error(cell, cell_index, exec_reply)
  File "C:\Users\unerue\miniconda3\envs\jupyterbook\lib\site-packages\nbclient\client.py", line 862, in _check_raise_for_error
    raise CellExecutionError.from_cell_and_msg(cell, exec_reply_content)
nbclient.exceptions.CellExecutionError: An error occurred while executing the following cell:
------------------
import cv2
import numpy as np
import matplotlib.pyplot as plt

img = cv2.imread('./img/cat-01.jpg')
img = img[..., ::-1]

kernel = np.array([
    [0.04, 0.04, 0.04, 0.04, 0.04],
    [0.04, 0.04, 0.04, 0.04, 0.04],
    [0.04, 0.04, 0.04, 0.04, 0.04],
    [0.04, 0.04, 0.04, 0.04, 0.04],
    [0.04, 0.04, 0.04, 0.04, 0.04],
])

kernel = np.ones((5, 5)) / 5**2
blured1 = cv2.filter2D(img, -1, kernel)
blured2 = cv2.blur(img, (10, 10))


fig, (ax1, ax2, ax3) = plt.subplots(ncols=3)
ax1.imshow(img)
ax2.imshow(blured1)
ax3.imshow(blured2)
fig.tight_layout()
plt.show()
------------------

[1;31m---------------------------------------------------------------------------[0m
[1;31mModuleNotFoundError[0m                       Traceback (most recent call last)
Cell [1;32mIn[1], line 1[0m
[1;32m----> 1[0m [38;5;28;01mimport[39;00m [38;5;21;01mcv2[39;00m
[0;32m      2[0m [38;5;28;01mimport[39;00m [38;5;21;01mnumpy[39;00m [38;5;28;01mas[39;00m [38;5;21;01mnp[39;00m
[0;32m      3[0m [38;5;28;01mimport[39;00m [38;5;21;01mmatplotlib[39;00m[38;5;21;01m.[39;00m[38;5;21;01mpyplot[39;00m [38;5;28;01mas[39;00m [38;5;21;01mplt[39;00m

[1;31mModuleNotFoundError[0m: No module named 'cv2'
ModuleNotFoundError: No module named 'cv2'

